<?xml version="1.0" ?>
<!-- =================================================================================== -->
<!-- |    This document was autogenerated by xacro from /home/wu/catkin_ws/src/mine/robot_models/allegro/urdf/allegro.urdf.xacro | -->
<!-- |    EDITING THIS FILE BY HAND IS NOT RECOMMENDED                                 | -->
<!-- =================================================================================== -->
<robot name="allegro">
  <!--
rosrun xacro xacro.py allegro_hand_description_right.urdf.xacro > allegro_hand_description_right.urdf
roslaunch launchers/fuerte/allegro_hand_jgui_right_virtual.launch 
-->
  <!-- ======================== BASE PARAMS ========================= -->
  <!-- ======================== FINGER PARAMS ======================== -->
  <!--0.002298-->
  <!-- ========================= THUMB PARAMS ========================= -->
  <!-- ========================= LIMITS ========================= -->
  <!-- ============================================================================= -->
  <!-- ============================================================================= -->
  <!-- ============================================================================= -->
  <!-- BASE -->
  <link name="base_link">
    <visual>
      <geometry>
        <mesh filename="package://allegro_hand_description/urdf/meshes/base_link.STL"/>
      </geometry>
      <!-- LEFT -->
      <!-- <origin rpy="${-90*DEG2RAD} 0 0" xyz="0 0 0 "/> -->
      <!-- RIGHT -->
      <origin rpy="0 0 0" xyz="0 0 0 "/>
      <material name="black">
        <color rgba="0.2 0.2 0.2 1"/>
      </material>
    </visual>
    <collision>
      <origin rpy="0 0 0" xyz="-0.009300 0 -0.0475"/>
      <geometry>
        <box size="0.0408 0.1130 0.095"/>
      </geometry>
    </collision>
  </link>
  <!-- ============================================================================= -->
  <!-- ============================================================================= -->
  <!-- ============================================================================= -->
  <!-- ============================================================================= -->
  <!-- END THUMB MACRO -->
  <!-- [[END]] THREE FINGER MACRO -->
  <!-- FINGERS -->
  <!-- [LINK 0, 4, 8] -->
  <link name="for_link_0">
    <visual>
      <geometry>
        <mesh filename="package://allegro_hand_description/urdf/meshes/link_0.0.STL"/>
      </geometry>
      <material name="black"/>
    </visual>
    <collision>
      <geometry>
        <box size="0.0196 0.0275 0.0164"/>
      </geometry>
      <origin rpy="0 0 0" xyz="0 0 0.0082"/>
    </collision>
  </link>
  <joint name="FFJ_0" type="revolute">
    <axis xyz="0 0 1"/>
    <limit effort="0" lower="-0.47" upper="0.47" velocity="1"/>
    <parent link="base_link"/>
    <child link="for_link_0"/>
    <origin rpy="-0.08726646254999999 0 0" xyz="0 0.0435 -0.001542"/>
  </joint>
  <!-- [LINK 1, 5, 9] -->
  <link name="for_link_1">
    <visual>
      <geometry>
        <mesh filename="package://allegro_hand_description/urdf/meshes/link_1.0.STL"/>
      </geometry>
      <material name="black"/>
    </visual>
    <collision>
      <geometry>
        <box size="0.0196 0.0275 0.054"/>
      </geometry>
      <origin rpy="0 0 0" xyz="0 0 0.027"/>
    </collision>
  </link>
  <joint name="FFJ_1" type="revolute">
    <limit effort="0" lower="-0.19599999999999998" upper="1.6099999999999999" velocity="1"/>
    <axis xyz="0 1 0"/>
    <parent link="for_link_0"/>
    <child link="for_link_1"/>
    <origin xyz="0 0 0.0164"/>
  </joint>
  <!-- [LINK 2, 6, 10]-->
  <link name="for_link_2">
    <visual>
      <geometry>
        <mesh filename="package://allegro_hand_description/urdf/meshes/link_2.0.STL"/>
      </geometry>
      <material name="black"/>
    </visual>
    <collision>
      <geometry>
        <box size="0.0196 0.0275 0.0384"/>
      </geometry>
      <origin rpy="0 0 0" xyz="0 0 0.0192"/>
    </collision>
  </link>
  <joint name="FFJ_2" type="revolute">
    <axis xyz="0 1 0"/>
    <limit effort="0" lower="-0.17400000000000002" upper="1.7089999999999999" velocity="1"/>
    <parent link="for_link_1"/>
    <child link="for_link_2"/>
    <origin xyz="0 0 0.054"/>
  </joint>
  <!-- [LINK 3, 7, 11] -->
  <link name="for_link_3">
    <visual>
      <geometry>
        <mesh filename="package://allegro_hand_description/urdf/meshes/link_3.0.STL"/>
      </geometry>
      <material name="black"/>
    </visual>
    <collision>
      <geometry>
        <box size="0.0196 0.0275 0.026699999999999998"/>
      </geometry>
      <origin rpy="0 0 0" xyz="0 0 0.013349999999999999"/>
    </collision>
  </link>
  <joint name="FFJ_3" type="revolute">
    <axis xyz="0 1 0"/>
    <limit effort="0" lower="-0.227" upper="1.6179999999999999" velocity="1"/>
    <parent link="for_link_2"/>
    <child link="for_link_3"/>
    <origin xyz="0 0 0.0384"/>
  </joint>
  <!-- [FINGER TIP] -->
  <link name="for_link_tip">
    <visual>
      <geometry>
        <mesh filename="package://allegro_hand_description/urdf/meshes/link_3.0_tip.STL"/>
      </geometry>
      <material name="white">
        <color rgba=".9 .9 .9 1"/>
      </material>
    </visual>
    <collision>
      <geometry>
        <sphere radius="0.012"/>
      </geometry>
    </collision>
  </link>
  <joint name="FFJ_tip" type="fixed">
    <parent link="for_link_3"/>
    <child link="for_link_tip"/>
    <origin rpy="0 0 0" xyz="0 0 0.026699999999999998"/>
  </joint>
  <!-- [LINK 0, 4, 8] -->
  <link name="mid_link_0">
    <visual>
      <geometry>
        <mesh filename="package://allegro_hand_description/urdf/meshes/link_0.0.STL"/>
      </geometry>
      <material name="black"/>
    </visual>
    <collision>
      <geometry>
        <box size="0.0196 0.0275 0.0164"/>
      </geometry>
      <origin rpy="0 0 0" xyz="0 0 0.0082"/>
    </collision>
  </link>
  <joint name="MFJ_0" type="revolute">
    <axis xyz="0 0 1"/>
    <limit effort="0" lower="-0.47" upper="0.47" velocity="1"/>
    <parent link="base_link"/>
    <child link="mid_link_0"/>
    <origin rpy="0.0 0 0" xyz="0 0 0.0007"/>
  </joint>
  <!-- [LINK 1, 5, 9] -->
  <link name="mid_link_1">
    <visual>
      <geometry>
        <mesh filename="package://allegro_hand_description/urdf/meshes/link_1.0.STL"/>
      </geometry>
      <material name="black"/>
    </visual>
    <collision>
      <geometry>
        <box size="0.0196 0.0275 0.054"/>
      </geometry>
      <origin rpy="0 0 0" xyz="0 0 0.027"/>
    </collision>
  </link>
  <joint name="MFJ_1" type="revolute">
    <limit effort="0" lower="-0.19599999999999998" upper="1.6099999999999999" velocity="1"/>
    <axis xyz="0 1 0"/>
    <parent link="mid_link_0"/>
    <child link="mid_link_1"/>
    <origin xyz="0 0 0.0164"/>
  </joint>
  <!-- [LINK 2, 6, 10]-->
  <link name="mid_link_2">
    <visual>
      <geometry>
        <mesh filename="package://allegro_hand_description/urdf/meshes/link_2.0.STL"/>
      </geometry>
      <material name="black"/>
    </visual>
    <collision>
      <geometry>
        <box size="0.0196 0.0275 0.0384"/>
      </geometry>
      <origin rpy="0 0 0" xyz="0 0 0.0192"/>
    </collision>
  </link>
  <joint name="MFJ_2" type="revolute">
    <axis xyz="0 1 0"/>
    <limit effort="0" lower="-0.17400000000000002" upper="1.7089999999999999" velocity="1"/>
    <parent link="mid_link_1"/>
    <child link="mid_link_2"/>
    <origin xyz="0 0 0.054"/>
  </joint>
  <!-- [LINK 3, 7, 11] -->
  <link name="mid_link_3">
    <visual>
      <geometry>
        <mesh filename="package://allegro_hand_description/urdf/meshes/link_3.0.STL"/>
      </geometry>
      <material name="black"/>
    </visual>
    <collision>
      <geometry>
        <box size="0.0196 0.0275 0.026699999999999998"/>
      </geometry>
      <origin rpy="0 0 0" xyz="0 0 0.013349999999999999"/>
    </collision>
  </link>
  <joint name="MFJ_3" type="revolute">
    <axis xyz="0 1 0"/>
    <limit effort="0" lower="-0.227" upper="1.6179999999999999" velocity="1"/>
    <parent link="mid_link_2"/>
    <child link="mid_link_3"/>
    <origin xyz="0 0 0.0384"/>
  </joint>
  <!-- [FINGER TIP] -->
  <link name="mid_link_tip">
    <visual>
      <geometry>
        <mesh filename="package://allegro_hand_description/urdf/meshes/link_3.0_tip.STL"/>
      </geometry>
      <material name="white">
        <color rgba=".9 .9 .9 1"/>
      </material>
    </visual>
    <collision>
      <geometry>
        <sphere radius="0.012"/>
      </geometry>
    </collision>
  </link>
  <joint name="MFJ_tip" type="fixed">
    <parent link="mid_link_3"/>
    <child link="mid_link_tip"/>
    <origin rpy="0 0 0" xyz="0 0 0.026699999999999998"/>
  </joint>
  <!-- [LINK 0, 4, 8] -->
  <link name="rin_link_0">
    <visual>
      <geometry>
        <mesh filename="package://allegro_hand_description/urdf/meshes/link_0.0.STL"/>
      </geometry>
      <material name="black"/>
    </visual>
    <collision>
      <geometry>
        <box size="0.0196 0.0275 0.0164"/>
      </geometry>
      <origin rpy="0 0 0" xyz="0 0 0.0082"/>
    </collision>
  </link>
  <joint name="RFJ_0" type="revolute">
    <axis xyz="0 0 1"/>
    <limit effort="0" lower="-0.47" upper="0.47" velocity="1"/>
    <parent link="base_link"/>
    <child link="rin_link_0"/>
    <origin rpy="0.08726646254999999 0 0" xyz="0 -0.0435 -0.001542"/>
  </joint>
  <!-- [LINK 1, 5, 9] -->
  <link name="rin_link_1">
    <visual>
      <geometry>
        <mesh filename="package://allegro_hand_description/urdf/meshes/link_1.0.STL"/>
      </geometry>
      <material name="black"/>
    </visual>
    <collision>
      <geometry>
        <box size="0.0196 0.0275 0.054"/>
      </geometry>
      <origin rpy="0 0 0" xyz="0 0 0.027"/>
    </collision>
  </link>
  <joint name="RFJ_1" type="revolute">
    <limit effort="0" lower="-0.19599999999999998" upper="1.6099999999999999" velocity="1"/>
    <axis xyz="0 1 0"/>
    <parent link="rin_link_0"/>
    <child link="rin_link_1"/>
    <origin xyz="0 0 0.0164"/>
  </joint>
  <!-- [LINK 2, 6, 10]-->
  <link name="rin_link_2">
    <visual>
      <geometry>
        <mesh filename="package://allegro_hand_description/urdf/meshes/link_2.0.STL"/>
      </geometry>
      <material name="black"/>
    </visual>
    <collision>
      <geometry>
        <box size="0.0196 0.0275 0.0384"/>
      </geometry>
      <origin rpy="0 0 0" xyz="0 0 0.0192"/>
    </collision>
  </link>
  <joint name="RFJ_2" type="revolute">
    <axis xyz="0 1 0"/>
    <limit effort="0" lower="-0.17400000000000002" upper="1.7089999999999999" velocity="1"/>
    <parent link="rin_link_1"/>
    <child link="rin_link_2"/>
    <origin xyz="0 0 0.054"/>
  </joint>
  <!-- [LINK 3, 7, 11] -->
  <link name="rin_link_3">
    <visual>
      <geometry>
        <mesh filename="package://allegro_hand_description/urdf/meshes/link_3.0.STL"/>
      </geometry>
      <material name="black"/>
    </visual>
    <collision>
      <geometry>
        <box size="0.0196 0.0275 0.026699999999999998"/>
      </geometry>
      <origin rpy="0 0 0" xyz="0 0 0.013349999999999999"/>
    </collision>
  </link>
  <joint name="RFJ_3" type="revolute">
    <axis xyz="0 1 0"/>
    <limit effort="0" lower="-0.227" upper="1.6179999999999999" velocity="1"/>
    <parent link="rin_link_2"/>
    <child link="rin_link_3"/>
    <origin xyz="0 0 0.0384"/>
  </joint>
  <!-- [FINGER TIP] -->
  <link name="rin_link_tip">
    <visual>
      <geometry>
        <mesh filename="package://allegro_hand_description/urdf/meshes/link_3.0_tip.STL"/>
      </geometry>
      <material name="white">
        <color rgba=".9 .9 .9 1"/>
      </material>
    </visual>
    <collision>
      <geometry>
        <sphere radius="0.012"/>
      </geometry>
    </collision>
  </link>
  <joint name="RFJ_tip" type="fixed">
    <parent link="rin_link_3"/>
    <child link="rin_link_tip"/>
    <origin rpy="0 0 0" xyz="0 0 0.026699999999999998"/>
  </joint>
  <!-- THUMB -->
  <!-- [LINK 12] -->
  <link name="thu_link_0">
    <visual>
      <geometry>
        <!-- RIGHT -->
        <mesh filename="package://allegro_hand_description/urdf/meshes/link_12.0_right.STL"/>
        <!-- LEFT -->
        <!-- <mesh filename="package://allegro_hand_description/urdf/meshes/link_12.0_left.STL" /> -->
      </geometry>
      <material name="black">
        <color rgba=".2 .2 .2 1"/>
      </material>
    </visual>
    <collision>
      <geometry>
        <box size="0.0358 0.034 0.0455"/>
      </geometry>
      <!-- RIGHT -->
      <origin rpy="0 0 0" xyz="-0.0179 0.009 0.0145"/>
      <!-- LEFT -->
      <!-- <origin rpy="0 0 0" xyz="${-0.0358/2+0.0} ${-.018/2} ${.029/2}"/> -->
    </collision>
  </link>
  <joint name="THJ_0" type="revolute">
    <axis xyz="-1 0 0"/>
    <limit effort="0" lower="0.263" upper="1.396" velocity="1"/>
    <parent link="base_link"/>
    <child link="thu_link_0"/>
    <origin rpy="0 -1.6580627884499999 -1.5707963259" xyz="-0.0182 0.019333 -0.045987"/>
  </joint>
  <!-- [LINK 13] -->
  <link name="thu_link_1">
    <visual>
      <geometry>
        <mesh filename="package://allegro_hand_description/urdf/meshes/link_13.0.STL"/>
      </geometry>
      <material name="black">
        <color rgba=".2 .2 .2 1"/>
      </material>
    </visual>
    <collision>
      <geometry>
        <box size="0.0196 0.0275 0.0177"/>
      </geometry>
      <origin rpy="0 0 0" xyz="0 0 0.00885"/>
    </collision>
  </link>
  <joint name="THJ_1" type="revolute">
    <axis xyz="0 0 1"/>
    <limit effort="0" lower="-0.10499999999999998" upper="1.1629999999999998" velocity="1"/>
    <parent link="thu_link_0"/>
    <child link="thu_link_1"/>
    <!-- RIGHT -->
    <origin xyz="-0.027 0.005 0.0399"/>
    <!-- LEFT -->
    <!-- <origin xyz="-0.027 -0.005 0.0399"/> -->
  </joint>
  <!-- [LINK 14] -->
  <link name="thu_link_2">
    <visual>
      <geometry>
        <mesh filename="package://allegro_hand_description/urdf/meshes/link_14.0.STL"/>
      </geometry>
      <material name="black">
		  	</material>
    </visual>
    <collision>
      <geometry>
        <box size="0.0196 0.0275 0.0514"/>
      </geometry>
      <origin rpy="0 0 0" xyz="0 0 0.0257"/>
    </collision>
  </link>
  <joint name="THJ_2" type="revolute">
    <axis xyz="0 1 0"/>
    <limit effort="0" lower="-0.18899999999999997" upper="1.644" velocity="1"/>
    <parent link="thu_link_1"/>
    <child link="thu_link_2"/>
    <origin xyz="0 0 0.0177"/>
  </joint>
  <!-- [LINK 15] -->
  <link name="thu_link_3">
    <visual>
      <geometry>
        <mesh filename="package://allegro_hand_description/urdf/meshes/link_15.0.STL"/>
      </geometry>
      <material name="black">
    	</material>
    </visual>
    <collision>
      <geometry>
        <box size="0.0196 0.0275 0.042300000000000004"/>
      </geometry>
      <origin rpy="0 0 0" xyz="0 0 0.021150000000000002"/>
    </collision>
  </link>
  <joint name="THJ_3" type="revolute">
    <axis xyz="0 1 0"/>
    <limit effort="0" lower="-0.162" upper="1.7189999999999999" velocity="1"/>
    <parent link="thu_link_2"/>
    <child link="thu_link_3"/>
    <origin xyz="0 0 0.0514"/>
  </joint>
  <!-- [FINGER TIP] -->
  <link name="thu_link_tip">
    <visual>
      <geometry>
        <mesh filename="package://allegro_hand_description/urdf/meshes/link_15.0_tip.STL"/>
      </geometry>
      <material name="white">
        <color rgba=".9 .9 .9 1"/>
      </material>
    </visual>
    <collision>
      <geometry>
        <sphere radius="0.012"/>
      </geometry>
      <origin rpy="0 0 0" xyz="0 0 0"/>
    </collision>
  </link>
  <joint name="THJ_tip" type="fixed">
    <parent link="thu_link_3"/>
    <child link="thu_link_tip"/>
    <origin rpy="0 0 0" xyz="0 0 0.042300000000000004"/>
    <!--0.0267000000000005-->
  </joint>
  <!--
<xacro:thumb_left 
	finger_num=			"3" 
	offset_origin_x=	"-0.0182"	
	offset_origin_y=	"-0.019333" 
	offset_origin_z=	"-0.045987" 
	
	
	finger_angle_r=		"${90*DEG2RAD}"
	finger_angle_p=		"-${95*DEG2RAD}"	
	finger_angle_y=		"${90*DEG2RAD}"
/>
-->
  <link name="ik_palm"/>
  <joint name="ik_palm_joint" type="fixed">
    <parent link="base_link"/>
    <child link="ik_palm"/>
    <origin rpy="0.0 0.0 1.5707963267948963" xyz="0 0 0"/>
  </joint>
</robot>
